<?xml version="1.0" encoding="UTF-8"?>
<!-- Generated by org.testng.reporters.JUnitReportReporter -->
<testsuite hostname="DESKTOP-C2JSM5E" failures="1" tests="1" name="sql.testing.SQLConnector" time="0.129" errors="0" timestamp="23 Aug 2022 08:52:22 GMT">
  <testcase classname="sql.testing.SQLConnector" name="testData" time="0.129">
    <failure message="Communications link failure

The last packet sent successfully to the server was 0 milliseconds ago. The driver has not received any packets from the server." type="com.mysql.cj.jdbc.exceptions.CommunicationsException">
      <![CDATA[com.mysql.cj.jdbc.exceptions.CommunicationsException: Communications link failure

The last packet sent successfully to the server was 0 milliseconds ago. The driver has not received any packets from the server.
	at com.mysql.cj.jdbc.exceptions.SQLError.createCommunicationsException(SQLError.java:174)
	at com.mysql.cj.jdbc.exceptions.SQLExceptionsMapping.translateException(SQLExceptionsMapping.java:64)
	at com.mysql.cj.jdbc.ConnectionImpl.createNewIO(ConnectionImpl.java:828)
	at com.mysql.cj.jdbc.ConnectionImpl.<init>(ConnectionImpl.java:448)
	at com.mysql.cj.jdbc.ConnectionImpl.getInstance(ConnectionImpl.java:241)
	at com.mysql.cj.jdbc.NonRegisteringDriver.connect(NonRegisteringDriver.java:198)
	at java.sql/java.sql.DriverManager.getConnection(DriverManager.java:683)
	at java.sql/java.sql.DriverManager.getConnection(DriverManager.java:230)
	at sql.testing.SQLConnector.testData(SQLConnector.java:31)
	at java.base/jdk.internal.reflect.DirectMethodHandleAccessor.invoke(DirectMethodHandleAccessor.java:104)
	at java.base/java.lang.reflect.Method.invoke(Method.java:577)
	at org.testng.internal.MethodInvocationHelper.invokeMethod(MethodInvocationHelper.java:80)
	at org.testng.internal.Invoker.invokeMethod(Invoker.java:714)
	at org.testng.internal.Invoker.invokeTestMethod(Invoker.java:901)
	at org.testng.internal.Invoker.invokeTestMethods(Invoker.java:1231)
	at org.testng.internal.TestMethodWorker.invokeTestMethods(TestMethodWorker.java:127)
	at org.testng.internal.TestMethodWorker.run(TestMethodWorker.java:111)
	at org.testng.TestRunner.privateRun(TestRunner.java:767)
	at org.testng.TestRunner.run(TestRunner.java:617)
	at org.testng.SuiteRunner.runTest(SuiteRunner.java:334)
	at org.testng.SuiteRunner.runSequentially(SuiteRunner.java:329)
	at org.testng.SuiteRunner.privateRun(SuiteRunner.java:291)
	at org.testng.SuiteRunner.run(SuiteRunner.java:240)
	at org.testng.SuiteRunnerWorker.runSuite(SuiteRunnerWorker.java:52)
	at org.testng.SuiteRunnerWorker.run(SuiteRunnerWorker.java:86)
	at org.testng.TestNG.runSuitesSequentially(TestNG.java:1198)
	at org.testng.TestNG.runSuitesLocally(TestNG.java:1123)
	at org.testng.TestNG.run(TestNG.java:1031)
	at org.testng.remote.AbstractRemoteTestNG.run(AbstractRemoteTestNG.java:115)
	at org.testng.remote.RemoteTestNG.initAndRun(RemoteTestNG.java:251)
	at org.testng.remote.RemoteTestNG.main(RemoteTestNG.java:77)
Caused by: com.mysql.cj.exceptions.CJCommunicationsException: Communications link failure

The last packet sent successfully to the server was 0 milliseconds ago. The driver has not received any packets from the server.
	at java.base/jdk.internal.reflect.DirectConstructorHandleAccessor.newInstance(DirectConstructorHandleAccessor.java:67)
	at java.base/java.lang.reflect.Constructor.newInstanceWithCaller(Constructor.java:499)
	at java.base/java.lang.reflect.Constructor.newInstance(Constructor.java:483)
	at com.mysql.cj.exceptions.ExceptionFactory.createException(ExceptionFactory.java:61)
	at com.mysql.cj.exceptions.ExceptionFactory.createException(ExceptionFactory.java:105)
	at com.mysql.cj.exceptions.ExceptionFactory.createException(ExceptionFactory.java:151)
	at com.mysql.cj.exceptions.ExceptionFactory.createCommunicationsException(ExceptionFactory.java:167)
	at com.mysql.cj.protocol.a.NativeSocketConnection.connect(NativeSocketConnection.java:89)
	at com.mysql.cj.NativeSession.connect(NativeSession.java:120)
	at com.mysql.cj.jdbc.ConnectionImpl.connectOneTryOnly(ConnectionImpl.java:948)
	at com.mysql.cj.jdbc.ConnectionImpl.createNewIO(ConnectionImpl.java:818)
	... 28 more
Caused by: java.net.ConnectException: Connection refused: connect
	at java.base/sun.nio.ch.Net.connect0(Native Method)
	at java.base/sun.nio.ch.Net.connect(Net.java:579)
	at java.base/sun.nio.ch.Net.connect(Net.java:568)
	at java.base/sun.nio.ch.NioSocketImpl.connect(NioSocketImpl.java:585)
	at java.base/java.net.SocksSocketImpl.connect(SocksSocketImpl.java:327)
	at java.base/java.net.Socket.connect(Socket.java:633)
	at com.mysql.cj.protocol.StandardSocketFactory.connect(StandardSocketFactory.java:153)
	at com.mysql.cj.protocol.a.NativeSocketConnection.connect(NativeSocketConnection.java:63)
	... 31 more
]]>
    </failure>
  </testcase> <!-- testData -->
</testsuite> <!-- sql.testing.SQLConnector -->
